Workbook

Sheet tips
A1: sex | B1: sex_enc | C1: smoker | D1: smoker_enc | E1: day | F1: day_enc | G1: time | H1: time_enc | I1: size | J1: total_bill | K1: tip | L1: predicted_tip | M1: Error | N1: Squares Error
A2: Female | B2: =IF(A2="Male",1,0) -> 0 | C2: No | D2: =IF(C2="Yes",1,0) -> 0 | E2: Sun | F2: =IF(E2="Thur",1,IF(E2="Fri",2,IF(E2="Sat",3,4))) -> 4 | G2: Dinner | H2: =IF(G2="Dinner",1,0) -> 1 | I2: 2 | J2: 16.99 | K2: 1.01 | L2: =$Q$57 + $Q$58*B2 + $Q$59*D2 + $Q$62*F2 + $Q$61*H2 + $Q$60*I2 + $Q$63*J2 -> 2.96648 | M2: =K2-L2 -> -1.95648 | N2: =M2^2 -> 3.8278138
A3: Male | B3: =IF(A3="Male",1,0) -> 1 | C3: No | D3: =IF(C3="Yes",1,0) -> 0 | E3: Sun | F3: =IF(E3="Thur",1,IF(E3="Fri",2,IF(E3="Sat",3,4))) -> 4 | G3: Dinner | H3: =IF(G3="Dinner",1,0) -> 1 | I3: 3 | J3: 10.34 | K3: 1.66 | L3: =$Q$57 + $Q$58*B3 + $Q$59*D3 + $Q$62*F3 + $Q$61*H3 + $Q$60*I3 + $Q$63*J3 -> 2.3560003 | M3: =K3-L3 -> -0.69600035 | N3: =M3^2 -> 0.48441649 | Q3: RMSE formula for Squared Error column
A4: Male | B4: =IF(A4="Male",1,0) -> 1 | C4: No | D4: =IF(C4="Yes",1,0) -> 0 | E4: Sun | F4: =IF(E4="Thur",1,IF(E4="Fri",2,IF(E4="Sat",3,4))) -> 4 | G4: Dinner | H4: =IF(G4="Dinner",1,0) -> 1 | I4: 3 | J4: 21.01 | K4: 3.5 | L4: =$Q$57 + $Q$58*B4 + $Q$59*D4 + $Q$62*F4 + $Q$61*H4 + $Q$60*I4 + $Q$63*J4 -> 3.3617921 | M4: =K4-L4 -> 0.13820791 | N4: =M4^2 -> 0.019101426 | Q4: =SQRT(AVERAGE(N2:N244)) -> 1.0218611
A5: Male | B5: =IF(A5="Male",1,0) -> 1 | C5: No | D5: =IF(C5="Yes",1,0) -> 0 | E5: Sun | F5: =IF(E5="Thur",1,IF(E5="Fri",2,IF(E5="Sat",3,4))) -> 4 | G5: Dinner | H5: =IF(G5="Dinner",1,0) -> 1 | I5: 2 | J5: 23.68 | K5: 3.31 | L5: =$Q$57 + $Q$58*B5 + $Q$59*D5 + $Q$62*F5 + $Q$61*H5 + $Q$60*I5 + $Q$63*J5 -> 3.5604704 | M5: =K5-L5 -> -0.25047038 | N5: =M5^2 -> 0.062735412
A6: Female | B6: =IF(A6="Male",1,0) -> 0 | C6: No | D6: =IF(C6="Yes",1,0) -> 0 | E6: Sun | F6: =IF(E6="Thur",1,IF(E6="Fri",2,IF(E6="Sat",3,4))) -> 4 | G6: Dinner | H6: =IF(G6="Dinner",1,0) -> 1 | I6: 4 | J6: 24.59 | K6: 3.61 | L6: =$Q$57 + $Q$58*B6 + $Q$59*D6 + $Q$62*F6 + $Q$61*H6 + $Q$60*I6 + $Q$63*J6 -> 3.7888933 | M6: =K6-L6 -> -0.17889331 | N6: =M6^2 -> 0.032002816
A7: Male | B7: =IF(A7="Male",1,0) -> 1 | C7: No | D7: =IF(C7="Yes",1,0) -> 0 | E7: Sun | F7: =IF(E7="Thur",1,IF(E7="Fri",2,IF(E7="Sat",3,4))) -> 4 | G7: Dinner | H7: =IF(G7="Dinner",1,0) -> 1 | I7: 4 | J7: 25.29 | K7: 4.71 | L7: =$Q$57 + $Q$58*B7 + $Q$59*D7 + $Q$62*F7 + $Q$61*H7 + $Q$60*I7 + $Q$63*J7 -> 3.8182453 | M7: =K7-L7 -> 0.89175474 | N7: =M7^2 -> 0.79522652 | P7: sex | Q7: Gender of the customer
A8: Male | B8: =IF(A8="Male",1,0) -> 1 | C8: No | D8: =IF(C8="Yes",1,0) -> 0 | E8: Sun | F8: =IF(E8="Thur",1,IF(E8="Fri",2,IF(E8="Sat",3,4))) -> 4 | G8: Dinner | H8: =IF(G8="Dinner",1,0) -> 1 | I8: 2 | J8: 8.77 | K8: 2 | L8: =$Q$57 + $Q$58*B8 + $Q$59*D8 + $Q$62*F8 + $Q$61*H8 + $Q$60*I8 + $Q$63*J8 -> 2.1550013 | M8: =K8-L8 -> -0.15500132 | N8: =M8^2 -> 0.024025409 | P8: smoker | Q8: Indicates if the customer is a smoker or not
A9: Male | B9: =IF(A9="Male",1,0) -> 1 | C9: No | D9: =IF(C9="Yes",1,0) -> 0 | E9: Sun | F9: =IF(E9="Thur",1,IF(E9="Fri",2,IF(E9="Sat",3,4))) -> 4 | G9: Dinner | H9: =IF(G9="Dinner",1,0) -> 1 | I9: 4 | J9: 26.88 | K9: 3.12 | L9: =$Q$57 + $Q$58*B9 + $Q$59*D9 + $Q$62*F9 + $Q$61*H9 + $Q$60*I9 + $Q$63*J9 -> 3.9681243 | M9: =K9-L9 -> -0.84812425 | N9: =M9^2 -> 0.71931475 | P9: day | Q9: Day of the restaurant visit
A10: Male | B10: =IF(A10="Male",1,0) -> 1 | C10: No | D10: =IF(C10="Yes",1,0) -> 0 | E10: Sun | F10: =IF(E10="Thur",1,IF(E10="Fri",2,IF(E10="Sat",3,4))) -> 4 | G10: Dinner | H10: =IF(G10="Dinner",1,0) -> 1 | I10: 2 | J10: 15.04 | K10: 1.96 | L10: =$Q$57 + $Q$58*B10 + $Q$59*D10 + $Q$62*F10 + $Q$61*H10 + $Q$60*I10 + $Q$63*J10 -> 2.7460336 | M10: =K10-L10 -> -0.78603358 | N10: =M10^2 -> 0.61784879 | P10: time | Q10: Indicates whether the tip was for lunch or dinner
A11: Male | B11: =IF(A11="Male",1,0) -> 1 | C11: No | D11: =IF(C11="Yes",1,0) -> 0 | E11: Sun | F11: =IF(E11="Thur",1,IF(E11="Fri",2,IF(E11="Sat",3,4))) -> 4 | G11: Dinner | H11: =IF(G11="Dinner",1,0) -> 1 | I11: 2 | J11: 14.78 | K11: 3.23 | L11: =$Q$57 + $Q$58*B11 + $Q$59*D11 + $Q$62*F11 + $Q$61*H11 + $Q$60*I11 + $Q$63*J11 -> 2.7215251 | M11: =K11-L11 -> 0.50847493 | N11: =M11^2 -> 0.25854676 | P11: size | Q11: Number of members dining
A12: Male | B12: =IF(A12="Male",1,0) -> 1 | C12: No | D12: =IF(C12="Yes",1,0) -> 0 | E12: Sun | F12: =IF(E12="Thur",1,IF(E12="Fri",2,IF(E12="Sat",3,4))) -> 4 | G12: Dinner | H12: =IF(G12="Dinner",1,0) -> 1 | I12: 2 | J12: 10.27 | K12: 1.71 | L12: =$Q$57 + $Q$58*B12 + $Q$59*D12 + $Q$62*F12 + $Q$61*H12 + $Q$60*I12 + $Q$63*J12 -> 2.2963966 | M12: =K12-L12 -> -0.5863966 | N12: =M12^2 -> 0.34386097 | P12: total bill | Q12: Bill amount in USD
A13: Female | B13: =IF(A13="Male",1,0) -> 0 | C13: No | D13: =IF(C13="Yes",1,0) -> 0 | E13: Sun | F13: =IF(E13="Thur",1,IF(E13="Fri",2,IF(E13="Sat",3,4))) -> 4 | G13: Dinner | H13: =IF(G13="Dinner",1,0) -> 1 | I13: 4 | J13: 35.26 | K13: 5 | L13: =$Q$57 + $Q$58*B13 + $Q$59*D13 + $Q$62*F13 + $Q$61*H13 + $Q$60*I13 + $Q$63*J13 -> 4.7946851 | M13: =K13-L13 -> 0.20531495 | N13: =M13^2 -> 0.042154228 | P13: tip | Q13: Tip amount in USD
A14: Male | B14: =IF(A14="Male",1,0) -> 1 | C14: No | D14: =IF(C14="Yes",1,0) -> 0 | E14: Sun | F14: =IF(E14="Thur",1,IF(E14="Fri",2,IF(E14="Sat",3,4))) -> 4 | G14: Dinner | H14: =IF(G14="Dinner",1,0) -> 1 | I14: 2 | J14: 15.42 | K14: 1.57 | L14: =$Q$57 + $Q$58*B14 + $Q$59*D14 + $Q$62*F14 + $Q$61*H14 + $Q$60*I14 + $Q$63*J14 -> 2.7818537 | M14: =K14-L14 -> -1.2118537 | N14: =M14^2 -> 1.4685894
A15: Male | B15: =IF(A15="Male",1,0) -> 1 | C15: No | D15: =IF(C15="Yes",1,0) -> 0 | E15: Sun | F15: =IF(E15="Thur",1,IF(E15="Fri",2,IF(E15="Sat",3,4))) -> 4 | G15: Dinner | H15: =IF(G15="Dinner",1,0) -> 1 | I15: 4 | J15: 18.43 | K15: 3 | L15: =$Q$57 + $Q$58*B15 + $Q$59*D15 + $Q$62*F15 + $Q$61*H15 + $Q$60*I15 + $Q$63*J15 -> 3.1715975 | M15: =K15-L15 -> -0.17159752 | N15: =M15^2 -> 0.029445709
A16: Female | B16: =IF(A16="Male",1,0) -> 0 | C16: No | D16: =IF(C16="Yes",1,0) -> 0 | E16: Sun | F16: =IF(E16="Thur",1,IF(E16="Fri",2,IF(E16="Sat",3,4))) -> 4 | G16: Dinner | H16: =IF(G16="Dinner",1,0) -> 1 | I16: 2 | J16: 14.83 | K16: 3.02 | L16: =$Q$57 + $Q$58*B16 + $Q$59*D16 + $Q$62*F16 + $Q$61*H16 + $Q$60*I16 + $Q$63*J16 -> 2.7628708 | M16: =K16-L16 -> 0.25712924 | N16: =M16^2 -> 0.066115448 | Q16: Note 1 :
A17: Male | B17: =IF(A17="Male",1,0) -> 1 | C17: No | D17: =IF(C17="Yes",1,0) -> 0 | E17: Sun | F17: =IF(E17="Thur",1,IF(E17="Fri",2,IF(E17="Sat",3,4))) -> 4 | G17: Dinner | H17: =IF(G17="Dinner",1,0) -> 1 | I17: 2 | J17: 21.58 | K17: 3.92 | L17: =$Q$57 + $Q$58*B17 + $Q$59*D17 + $Q$62*F17 + $Q$61*H17 + $Q$60*I17 + $Q$63*J17 -> 3.362517 | M17: =K17-L17 -> 0.55748301 | N17: =M17^2 -> 0.3107873 | Q17: Dependent variable (Y):
A18: Female | B18: =IF(A18="Male",1,0) -> 0 | C18: No | D18: =IF(C18="Yes",1,0) -> 0 | E18: Sun | F18: =IF(E18="Thur",1,IF(E18="Fri",2,IF(E18="Sat",3,4))) -> 4 | G18: Dinner | H18: =IF(G18="Dinner",1,0) -> 1 | I18: 3 | J18: 10.33 | K18: 1.67 | L18: =$Q$57 + $Q$58*B18 + $Q$59*D18 + $Q$62*F18 + $Q$61*H18 + $Q$60*I18 + $Q$63*J18 -> 2.3916902 | M18: =K18-L18 -> -0.72169023 | N18: =M18^2 -> 0.52083679 | Q18: tip (the value we are predicting)
A19: Male | B19: =IF(A19="Male",1,0) -> 1 | C19: No | D19: =IF(C19="Yes",1,0) -> 0 | E19: Sun | F19: =IF(E19="Thur",1,IF(E19="Fri",2,IF(E19="Sat",3,4))) -> 4 | G19: Dinner | H19: =IF(G19="Dinner",1,0) -> 1 | I19: 3 | J19: 16.29 | K19: 3.71 | L19: =$Q$57 + $Q$58*B19 + $Q$59*D19 + $Q$62*F19 + $Q$61*H19 + $Q$60*I19 + $Q$63*J19 -> 2.9168683 | M19: =K19-L19 -> 0.79313172 | N19: =M19^2 -> 0.62905792
A20: Female | B20: =IF(A20="Male",1,0) -> 0 | C20: No | D20: =IF(C20="Yes",1,0) -> 0 | E20: Sun | F20: =IF(E20="Thur",1,IF(E20="Fri",2,IF(E20="Sat",3,4))) -> 4 | G20: Dinner | H20: =IF(G20="Dinner",1,0) -> 1 | I20: 3 | J20: 16.97 | K20: 3.5 | L20: =$Q$57 + $Q$58*B20 + $Q$59*D20 + $Q$62*F20 + $Q$61*H20 + $Q$60*I20 + $Q$63*J20 -> 3.0176 | M20: =K20-L20 -> 0.48240001 | N20: =M20^2 -> 0.23270977 | Q20: Independent variables (X):
A21: Male | B21: =IF(A21="Male",1,0) -> 1 | C21: No | D21: =IF(C21="Yes",1,0) -> 0 | E21: Sat | F21: =IF(E21="Thur",1,IF(E21="Fri",2,IF(E21="Sat",3,4))) -> 3 | G21: Dinner | H21: =IF(G21="Dinner",1,0) -> 1 | I21: 3 | J21: 20.65 | K21: 3.35 | L21: =$Q$57 + $Q$58*B21 + $Q$59*D21 + $Q$62*F21 + $Q$61*H21 + $Q$60*I21 + $Q$63*J21 -> 3.1528929 | M21: =K21-L21 -> 0.19710715 | N21: =M21^2 -> 0.038851227 | Q21: sex
A22: Male | B22: =IF(A22="Male",1,0) -> 1 | C22: No | D22: =IF(C22="Yes",1,0) -> 0 | E22: Sat | F22: =IF(E22="Thur",1,IF(E22="Fri",2,IF(E22="Sat",3,4))) -> 3 | G22: Dinner | H22: =IF(G22="Dinner",1,0) -> 1 | I22: 2 | J22: 17.92 | K22: 4.08 | L22: =$Q$57 + $Q$58*B22 + $Q$59*D22 + $Q$62*F22 + $Q$61*H22 + $Q$60*I22 + $Q$63*J22 -> 2.8425481 | M22: =K22-L22 -> 1.2374519 | N22: =M22^2 -> 1.5312871 | Q22: smoker
A23: Female | B23: =IF(A23="Male",1,0) -> 0 | C23: No | D23: =IF(C23="Yes",1,0) -> 0 | E23: Sat | F23: =IF(E23="Thur",1,IF(E23="Fri",2,IF(E23="Sat",3,4))) -> 3 | G23: Dinner | H23: =IF(G23="Dinner",1,0) -> 1 | I23: 2 | J23: 20.29 | K23: 2.75 | L23: =$Q$57 + $Q$58*B23 + $Q$59*D23 + $Q$62*F23 + $Q$61*H23 + $Q$60*I23 + $Q$63*J23 -> 3.1025852 | M23: =K23-L23 -> -0.3525852 | N23: =M23^2 -> 0.12431632 | Q23: day
A24: Female | B24: =IF(A24="Male",1,0) -> 0 | C24: No | D24: =IF(C24="Yes",1,0) -> 0 | E24: Sat | F24: =IF(E24="Thur",1,IF(E24="Fri",2,IF(E24="Sat",3,4))) -> 3 | G24: Dinner | H24: =IF(G24="Dinner",1,0) -> 1 | I24: 2 | J24: 15.77 | K24: 2.23 | L24: =$Q$57 + $Q$58*B24 + $Q$59*D24 + $Q$62*F24 + $Q$61*H24 + $Q$60*I24 + $Q$63*J24 -> 2.6765141 | M24: =K24-L24 -> -0.44651409 | N24: =M24^2 -> 0.19937484 | Q24: time
A25: Male | B25: =IF(A25="Male",1,0) -> 1 | C25: No | D25: =IF(C25="Yes",1,0) -> 0 | E25: Sat | F25: =IF(E25="Thur",1,IF(E25="Fri",2,IF(E25="Sat",3,4))) -> 3 | G25: Dinner | H25: =IF(G25="Dinner",1,0) -> 1 | I25: 4 | J25: 39.42 | K25: 7.58 | L25: =$Q$57 + $Q$58*B25 + $Q$59*D25 + $Q$62*F25 + $Q$61*H25 + $Q$60*I25 + $Q$63*J25 -> 4.9752244 | M25: =K25-L25 -> 2.6047756 | N25: =M25^2 -> 6.7848559 | Q25: size
A26: Male | B26: =IF(A26="Male",1,0) -> 1 | C26: No | D26: =IF(C26="Yes",1,0) -> 0 | E26: Sat | F26: =IF(E26="Thur",1,IF(E26="Fri",2,IF(E26="Sat",3,4))) -> 3 | G26: Dinner | H26: =IF(G26="Dinner",1,0) -> 1 | I26: 2 | J26: 19.82 | K26: 3.18 | L26: =$Q$57 + $Q$58*B26 + $Q$59*D26 + $Q$62*F26 + $Q$61*H26 + $Q$60*I26 + $Q$63*J26 -> 3.0216488 | M26: =K26-L26 -> 0.15835117 | N26: =M26^2 -> 0.025075093 | Q26: total bill
A27: Male | B27: =IF(A27="Male",1,0) -> 1 | C27: No | D27: =IF(C27="Yes",1,0) -> 0 | E27: Sat | F27: =IF(E27="Thur",1,IF(E27="Fri",2,IF(E27="Sat",3,4))) -> 3 | G27: Dinner | H27: =IF(G27="Dinner",1,0) -> 1 | I27: 4 | J27: 17.81 | K27: 2.34 | L27: =$Q$57 + $Q$58*B27 + $Q$59*D27 + $Q$62*F27 + $Q$61*H27 + $Q$60*I27 + $Q$63*J27 -> 2.9381898 | M27: =K27-L27 -> -0.59818977 | N27: =M27^2 -> 0.357831
A28: Male | B28: =IF(A28="Male",1,0) -> 1 | C28: No | D28: =IF(C28="Yes",1,0) -> 0 | E28: Sat | F28: =IF(E28="Thur",1,IF(E28="Fri",2,IF(E28="Sat",3,4))) -> 3 | G28: Dinner | H28: =IF(G28="Dinner",1,0) -> 1 | I28: 2 | J28: 13.37 | K28: 2 | L28: =$Q$57 + $Q$58*B28 + $Q$59*D28 + $Q$62*F28 + $Q$61*H28 + $Q$60*I28 + $Q$63*J28 -> 2.4136491 | M28: =K28-L28 -> -0.41364913 | N28: =M28^2 -> 0.17110561 | Q28: Note 2:
A29: Male | B29: =IF(A29="Male",1,0) -> 1 | C29: No | D29: =IF(C29="Yes",1,0) -> 0 | E29: Sat | F29: =IF(E29="Thur",1,IF(E29="Fri",2,IF(E29="Sat",3,4))) -> 3 | G29: Dinner | H29: =IF(G29="Dinner",1,0) -> 1 | I29: 2 | J29: 12.69 | K29: 2 | L29: =$Q$57 + $Q$58*B29 + $Q$59*D29 + $Q$62*F29 + $Q$61*H29 + $Q$60*I29 + $Q$63*J29 -> 2.3495499 | M29: =K29-L29 -> -0.34954994 | N29: =M29^2 -> 0.12218516 | Q29: This is a regression problem because the output variable (tip) is numeric
A30: Male | B30: =IF(A30="Male",1,0) -> 1 | C30: No | D30: =IF(C30="Yes",1,0) -> 0 | E30: Sat | F30: =IF(E30="Thur",1,IF(E30="Fri",2,IF(E30="Sat",3,4))) -> 3 | G30: Dinner | H30: =IF(G30="Dinner",1,0) -> 1 | I30: 2 | J30: 21.7 | K30: 4.3 | L30: =$Q$57 + $Q$58*B30 + $Q$59*D30 + $Q$62*F30 + $Q$61*H30 + $Q$60*I30 + $Q$63*J30 -> 3.1988642 | M30: =K30-L30 -> 1.1011358 | N30: =M30^2 -> 1.2125
A31: Female | B31: =IF(A31="Male",1,0) -> 0 | C31: No | D31: =IF(C31="Yes",1,0) -> 0 | E31: Sat | F31: =IF(E31="Thur",1,IF(E31="Fri",2,IF(E31="Sat",3,4))) -> 3 | G31: Dinner | H31: =IF(G31="Dinner",1,0) -> 1 | I31: 2 | J31: 19.65 | K31: 3 | L31: =$Q$57 + $Q$58*B31 + $Q$59*D31 + $Q$62*F31 + $Q$61*H31 + $Q$60*I31 + $Q$63*J31 -> 3.0422565 | M31: =K31-L31 -> -0.042256546 | N31: =M31^2 -> 0.0017856157 | P31: Variables | Q31: Correlation with tip
A32: Male | B32: =IF(A32="Male",1,0) -> 1 | C32: No | D32: =IF(C32="Yes",1,0) -> 0 | E32: Sat | F32: =IF(E32="Thur",1,IF(E32="Fri",2,IF(E32="Sat",3,4))) -> 3 | G32: Dinner | H32: =IF(G32="Dinner",1,0) -> 1 | I32: 2 | J32: 9.55 | K32: 1.45 | L32: =$Q$57 + $Q$58*B32 + $Q$59*D32 + $Q$62*F32 + $Q$61*H32 + $Q$60*I32 + $Q$63*J32 -> 2.0535625 | M32: =K32-L32 -> -0.60356249 | N32: =M32^2 -> 0.36428768 | P32: sex_enc | Q32: =CORREL(B1:B244, K1:K244) -> 0.085273975
A33: Male | B33: =IF(A33="Male",1,0) -> 1 | C33: No | D33: =IF(C33="Yes",1,0) -> 0 | E33: Sat | F33: =IF(E33="Thur",1,IF(E33="Fri",2,IF(E33="Sat",3,4))) -> 3 | G33: Dinner | H33: =IF(G33="Dinner",1,0) -> 1 | I33: 4 | J33: 18.35 | K33: 2.5 | L33: =$Q$57 + $Q$58*B33 + $Q$59*D33 + $Q$62*F33 + $Q$61*H33 + $Q$60*I33 + $Q$63*J33 -> 2.9890921 | M33: =K33-L33 -> -0.48909207 | N33: =M33^2 -> 0.23921105 | P33: smoker_enc | Q33: =CORREL(D1:D244, K1:K244) -> 0.00976275
A34: Female | B34: =IF(A34="Male",1,0) -> 0 | C34: No | D34: =IF(C34="Yes",1,0) -> 0 | E34: Sat | F34: =IF(E34="Thur",1,IF(E34="Fri",2,IF(E34="Sat",3,4))) -> 3 | G34: Dinner | H34: =IF(G34="Dinner",1,0) -> 1 | I34: 2 | J34: 15.06 | K34: 3 | L34: =$Q$57 + $Q$58*B34 + $Q$59*D34 + $Q$62*F34 + $Q$61*H34 + $Q$60*I34 + $Q$63*J34 -> 2.609587 | M34: =K34-L34 -> 0.390413 | N34: =M34^2 -> 0.15242231 | P34: day_enc | Q34: =CORREL(F1:F244, K1:K244) -> 0.13179753
A35: Female | B35: =IF(A35="Male",1,0) -> 0 | C35: No | D35: =IF(C35="Yes",1,0) -> 0 | E35: Sat | F35: =IF(E35="Thur",1,IF(E35="Fri",2,IF(E35="Sat",3,4))) -> 3 | G35: Dinner | H35: =IF(G35="Dinner",1,0) -> 1 | I35: 4 | J35: 20.69 | K35: 2.45 | L35: =$Q$57 + $Q$58*B35 + $Q$59*D35 + $Q$62*F35 + $Q$61*H35 + $Q$60*I35 + $Q$63*J35 -> 3.2463012 | M35: =K35-L35 -> -0.79630122 | N35: =M35^2 -> 0.63409563 | P35: time_enc | Q35: =CORREL(H1:H244, K1:K244) -> 0.11759639
A36: Male | B36: =IF(A36="Male",1,0) -> 1 | C36: No | D36: =IF(C36="Yes",1,0) -> 0 | E36: Sat | F36: =IF(E36="Thur",1,IF(E36="Fri",2,IF(E36="Sat",3,4))) -> 3 | G36: Dinner | H36: =IF(G36="Dinner",1,0) -> 1 | I36: 2 | J36: 17.78 | K36: 3.27 | L36: =$Q$57 + $Q$58*B36 + $Q$59*D36 + $Q$62*F36 + $Q$61*H36 + $Q$60*I36 + $Q$63*J36 -> 2.8293513 | M36: =K36-L36 -> 0.44064875 | N36: =M36^2 -> 0.19417132 | P36: size | Q36: =CORREL(I1:I244, K1:K244) -> 0.48840039
A37: Male | B37: =IF(A37="Male",1,0) -> 1 | C37: No | D37: =IF(C37="Yes",1,0) -> 0 | E37: Sat | F37: =IF(E37="Thur",1,IF(E37="Fri",2,IF(E37="Sat",3,4))) -> 3 | G37: Dinner | H37: =IF(G37="Dinner",1,0) -> 1 | I37: 3 | J37: 24.06 | K37: 3.6 | L37: =$Q$57 + $Q$58*B37 + $Q$59*D37 + $Q$62*F37 + $Q$61*H37 + $Q$60*I37 + $Q$63*J37 -> 3.4743315 | M37: =K37-L37 -> 0.12566855 | N37: =M37^2 -> 0.015792584 | P37: total bill | Q37: =CORREL(J1:J244, K1:K244) -> 0.67499786
A38: Male | B38: =IF(A38="Male",1,0) -> 1 | C38: No | D38: =IF(C38="Yes",1,0) -> 0 | E38: Sat | F38: =IF(E38="Thur",1,IF(E38="Fri",2,IF(E38="Sat",3,4))) -> 3 | G38: Dinner | H38: =IF(G38="Dinner",1,0) -> 1 | I38: 3 | J38: 16.31 | K38: 2 | L38: =$Q$57 + $Q$58*B38 + $Q$59*D38 + $Q$62*F38 + $Q$61*H38 + $Q$60*I38 + $Q$63*J38 -> 2.7437892 | M38: =K38-L38 -> -0.74378918 | N38: =M38^2 -> 0.55322235
A39: Female | B39: =IF(A39="Male",1,0) -> 0 | C39: No | D39: =IF(C39="Yes",1,0) -> 0 | E39: Sat | F39: =IF(E39="Thur",1,IF(E39="Fri",2,IF(E39="Sat",3,4))) -> 3 | G39: Dinner | H39: =IF(G39="Dinner",1,0) -> 1 | I39: 3 | J39: 16.93 | K39: 3.07 | L39: =$Q$57 + $Q$58*B39 + $Q$59*D39 + $Q$62*F39 + $Q$61*H39 + $Q$60*I39 + $Q$63*J39 -> 2.8388651 | M39: =K39-L39 -> 0.23113492 | N39: =M39^2 -> 0.053423351 | P39: Regression Output using input range sheet and Tips column from tips sheet
A40: Male | B40: =IF(A40="Male",1,0) -> 1 | C40: No | D40: =IF(C40="Yes",1,0) -> 0 | E40: Sat | F40: =IF(E40="Thur",1,IF(E40="Fri",2,IF(E40="Sat",3,4))) -> 3 | G40: Dinner | H40: =IF(G40="Dinner",1,0) -> 1 | I40: 3 | J40: 18.69 | K40: 2.31 | L40: =$Q$57 + $Q$58*B40 + $Q$59*D40 + $Q$62*F40 + $Q$61*H40 + $Q$60*I40 + $Q$63*J40 -> 2.9681364 | M40: =K40-L40 -> -0.65813636 | N40: =M40^2 -> 0.43314347
...

Sheet input range
A1: sex_enc | B1: smoker_enc | C1: day_enc | D1: time_enc | E1: size | F1: total_bill
A2: =IF(tips!A2="Male",1,0) -> 0 | B2: =IF(tips!C2="Yes",1,0) -> 0 | C2: =IF(tips!E2="Thur",1,IF(tips!E2="Fri",2,IF(tips!E2="Sat",3,4))) -> 4 | D2: =IF(tips!G2="Dinner",1,0) -> 1 | E2: 2 | F2: 16.99
A3: =IF(tips!A3="Male",1,0) -> 1 | B3: =IF(tips!C3="Yes",1,0) -> 0 | C3: =IF(tips!E3="Thur",1,IF(tips!E3="Fri",2,IF(tips!E3="Sat",3,4))) -> 4 | D3: =IF(tips!G3="Dinner",1,0) -> 1 | E3: 3 | F3: 10.34
A4: =IF(tips!A4="Male",1,0) -> 1 | B4: =IF(tips!C4="Yes",1,0) -> 0 | C4: =IF(tips!E4="Thur",1,IF(tips!E4="Fri",2,IF(tips!E4="Sat",3,4))) -> 4 | D4: =IF(tips!G4="Dinner",1,0) -> 1 | E4: 3 | F4: 21.01
A5: =IF(tips!A5="Male",1,0) -> 1 | B5: =IF(tips!C5="Yes",1,0) -> 0 | C5: =IF(tips!E5="Thur",1,IF(tips!E5="Fri",2,IF(tips!E5="Sat",3,4))) -> 4 | D5: =IF(tips!G5="Dinner",1,0) -> 1 | E5: 2 | F5: 23.68
A6: =IF(tips!A6="Male",1,0) -> 0 | B6: =IF(tips!C6="Yes",1,0) -> 0 | C6: =IF(tips!E6="Thur",1,IF(tips!E6="Fri",2,IF(tips!E6="Sat",3,4))) -> 4 | D6: =IF(tips!G6="Dinner",1,0) -> 1 | E6: 4 | F6: 24.59
A7: =IF(tips!A7="Male",1,0) -> 1 | B7: =IF(tips!C7="Yes",1,0) -> 0 | C7: =IF(tips!E7="Thur",1,IF(tips!E7="Fri",2,IF(tips!E7="Sat",3,4))) -> 4 | D7: =IF(tips!G7="Dinner",1,0) -> 1 | E7: 4 | F7: 25.29
A8: =IF(tips!A8="Male",1,0) -> 1 | B8: =IF(tips!C8="Yes",1,0) -> 0 | C8: =IF(tips!E8="Thur",1,IF(tips!E8="Fri",2,IF(tips!E8="Sat",3,4))) -> 4 | D8: =IF(tips!G8="Dinner",1,0) -> 1 | E8: 2 | F8: 8.77
A9: =IF(tips!A9="Male",1,0) -> 1 | B9: =IF(tips!C9="Yes",1,0) -> 0 | C9: =IF(tips!E9="Thur",1,IF(tips!E9="Fri",2,IF(tips!E9="Sat",3,4))) -> 4 | D9: =IF(tips!G9="Dinner",1,0) -> 1 | E9: 4 | F9: 26.88
A10: =IF(tips!A10="Male",1,0) -> 1 | B10: =IF(tips!C10="Yes",1,0) -> 0 | C10: =IF(tips!E10="Thur",1,IF(tips!E10="Fri",2,IF(tips!E10="Sat",3,4))) -> 4 | D10: =IF(tips!G10="Dinner",1,0) -> 1 | E10: 2 | F10: 15.04
A11: =IF(tips!A11="Male",1,0) -> 1 | B11: =IF(tips!C11="Yes",1,0) -> 0 | C11: =IF(tips!E11="Thur",1,IF(tips!E11="Fri",2,IF(tips!E11="Sat",3,4))) -> 4 | D11: =IF(tips!G11="Dinner",1,0) -> 1 | E11: 2 | F11: 14.78
A12: =IF(tips!A12="Male",1,0) -> 1 | B12: =IF(tips!C12="Yes",1,0) -> 0 | C12: =IF(tips!E12="Thur",1,IF(tips!E12="Fri",2,IF(tips!E12="Sat",3,4))) -> 4 | D12: =IF(tips!G12="Dinner",1,0) -> 1 | E12: 2 | F12: 10.27
A13: =IF(tips!A13="Male",1,0) -> 0 | B13: =IF(tips!C13="Yes",1,0) -> 0 | C13: =IF(tips!E13="Thur",1,IF(tips!E13="Fri",2,IF(tips!E13="Sat",3,4))) -> 4 | D13: =IF(tips!G13="Dinner",1,0) -> 1 | E13: 4 | F13: 35.26
... A244: =IF(tips!A244="Male",1,0) -> 0 | B244: =IF(tips!C244="Yes",1,0) -> 0 | C244: =IF(tips!E244="Thur",1,IF(tips!E244="Fri",2,IF(tips!E244="Sat",3,4))) -> 1 | D244: =IF(tips!G244="Dinner",1,0) -> 1 | E244: 2 | F244: 18.78
